Workbook

Sheet 0_GUIA_INTRO
B3: CUDI - Bienestar Animal
B4: Modelo de Flujos de Caja, Escenarios y Plan de Control
B5: Versión Académica y Profesional v6.1.7 (Optimizada en Español)
B7: ÍNDICE DEL MODELO FINANCIERO
B9: 0_GUIA_INTRO | C9: Portada, manual de colores e índice del simulador.
B10: 1_PANEL_CONTROL | C10: Panel central para la configuración manual de todo el modelo excel.
B11: 2_AJUSTES_MACRO | C11: Configuración de variables macro: WACC, Impuestos y periodos de amortización CAPEX.
B12: 3_HIPOTESIS_NEGOCIO | C12: Supuestos de negocio editables (Tarifas, Conversión, Churn, Costes AWS/Stripe/APIs).
B13: 4_PROY_DEMANDA | C13: Proyección mensual de demanda por producto para 3 escenarios en paralelo.
B14: 15_DASHBOARD_KPI | C14: Dashboard interactivo con selector de escenario y visualización de KPIs en tiempo real.
B15: 12_ANALISIS_ESCENARIOS | C15: Matriz comparativa de 3 escenarios (Negativo, Equilibrio y Positivo) a 3 años.
B16: 5_DETALLE_INGRESOS | C16: Proyección mensual de tráfico, CAC, altas, bajas de usuarios y desglose de monetización.
B17: 6_COSTES_COGS | C17: Desglose de costes directos asociados a la venta del servicio y del hardware (Smart Collar).
B18: 7_EQUIPO_RRHH | C18: Planificación mensual de nóminas bajo el modelo legal español/catalán (cotizaciones y topes).
B19: 8_COSTES_OPEX | C19: Gastos de estructura recurrentes (Coworking, software SaaS, SEO, eventos y marketing digital).
B20: 9_FLUJO_CAJA | C20: Detalle de inversiones iniciales, amortización mensual y estado de flujos de caja consolidado.
... B25: 17_ANALISIS_GRAFICO | C25: Dashboard ejecutivo con gráficos visuales y resumen financiero para soporte de decisiones.
B26: CÓDIGO DE COLORES DEL SIMULADOR
B28: Azul Claro Sombreado | C28: Celdas de Entrada Manual de Datos. Son las únicas celdas editables.
B29: Gris Claro | C29: Encabezados de Tabla, Fórmulas de Suma o Etiquetas Informativas.
B30: Verde Suave | C30: Celdas de KPI Positivos o Flujo de Caja Acumulado Positivo.
B31: Rojo Suave | C31: Celdas de KPI Críticos o Flujo de Caja Acumulado Negativo.
B32: Azul Slate | C32: Fórmula de Selector de Escenarios Activos.
A34: GUÍA DE NAVEGACIÓN Y ESTRUCTURA DEL MODELO
A35: 1. CÓDIGO DE COLORES DEL PROYECTO CUDI: - 🟦 AZUL: Infraestructura y Servidores. Costes de alojamiento AWS y APIs de IA (Claude y Gemini). - 🟨 AMARILLO: Marketing y Adquisición. Pauta digital (Facebook/TikTok Ads), branding y comisiones de venta. - 🟧 NARANJA: Hardware y Fabricación. Costes de fabricación física y stockage de Smart Collars. - 🟩 VERDE: Distribución y Logística. Coste de envío urgente y última milla a dueños de mascotas. - 🟪 PÚRPURA: Recursos Humanos, Estructura y Coworking. Nóminas, RETA, asesores y alquileres de oficinas. 2. NAVEGACIÓN Y USO DEL SIMULADOR: - Utilice el selector de la pestaña '1_PANEL_CONTROL' (Celda C4) para cambiar dinámicamente el escenario activo del modelo. - Las hojas están ordenadas de forma lógica: supuestos iniciales, proyección de demanda, ingresos y costes detallados, estados financieros consolidados, y finalmente las herramientas de control y gráficos interactivos.

Sheet 1_PANEL_CONTROL
B2: PANEL CENTRAL DE CONTROL DE DATOS Y PARÁMETROS
B3: Modifique únicamente las celdas sombreadas en azul claro. Todo el modelo se actualizará automáticamente.
B4: ESCENARIO DE DEMANDA ACTIVO (1=Negativo, 2=Equilibrio, 3=Positivo): | C4: 2 | D4: ← CAMBIE ESTE VALOR
B5: =CHOOSE('1_PANEL_CONTROL'!$C$4, "[NEGATIVO] PANEL DE CONTROL en Escenario Negativo. Se estiman bajas tasas de crecimiento (5%) y conversión (2,13%), con churn elevado (8%).", "[EQUILIBRIO] PANEL DE CONTROL en Escenario Equilibrio. Base del proyecto para break-even: 8% crecimiento, 2,00% conversión, 4,8% churn.", "[POSITIVO] PANEL DE CONTROL en Escenario Positivo. Supuestos optimistas: 15% crecimiento, 8% conversión, 3% churn.") -> [EQUILIBRIO] PANEL DE CONTROL en Escenario Equilibrio. Base del proyecto para break-even: 8% crecimiento, 2,00% conversión, 4,8% churn.
B6: 1. VARIABLES MACROECONÓMICAS Y FINANCIERAS
B7: Tasa de Impuesto sobre Sociedades | C7: 0.21 | D7: Tasa impositiva española para sociedades limitadas
B8: Tasa de Descuento (WACC) | C8: 0.1179 | D8: Costo promedio ponderado de capital para descontar flujos
B9: Valor Terminal de Salida | C9: 42000000 | D9: Valor terminal estimado del negocio al final del periodo
B10: Periodo de Amortización CAPEX (Meses) | C10: 60 | D10: Periodo en meses para amortizar las inversiones (5 Años de vida útil)
B11: Reserva Mínima de Caja | C11: 500 | D11: Saldo mínimo de seguridad requerido en caja de la empresa
B12: Tasa de Inflación Anual | C12: 0.03 | D12: Tasa de inflación anual proyectada para ajustar costes
B14: 2. SUSCRIPCIONES Y PRECIOS DE PRODUCTOS
B15: Precio Suscripción Premium Care CUDI (SaaS) | C15: 30 | D15: Cuota mensual del plan Premium Care
B16: Precio Venta Smart Collar (Hardware) | C16: 89.5 | D16: Precio de venta al público del dispositivo GPS
B17: Precio Seguro CUDI Shield Basic | C17: 18 | D17: Seguro de co-distribución mensual
B18: Precio Visita VetHome CUDI | C18: 75 | D18: Mensualidad de visita médica presencial a domicilio
B19: Ticket Medio Transacción Marketplace | C19: 25 | D19: Valor promedio de servicios del marketplace (paseos/estética)
B20: Comisión Marketplace (%) | C20: =CHOOSE('1_PANEL_CONTROL'!$C$4, 0.1, 0.15, 0.15) -> 0.15 | D20: Comisión (take-rate) dinámica según escenario (10%/15%/15%)
B21: Comisión Media Neta Marketplace (EUR) | C21: =C19*C20 -> 3.75 | D21: Cálculo de comisión neta por transacción en marketplace
B23: 3. COSTES DIRECTOS Y VARIABLES (COGS)
B24: Coste Fabricación Smart Collar (Hardware) | C24: 35 | D24: Coste unitario puesto en almacén (Landed Cost: incluye flete internacional y arancel UE del 3.7%)
B25: Coste de Mensajería y Envío Última Milla | C25: 6.5 | D25: Coste de transporte express para el collar
B26: Servidor AWS por cliente activo | C26: 0.6 | D26: Servidores e IoT Cloud mensual por usuario Premium
B27: Comisión Pasarela Pago (Stripe %) | C27: 0.025 | D27: Tasa de procesamiento de cobros recurrentes de Stripe
B28: Tarifa Fija API Gemini Flash | C28: 100 | D28: SaaS mensual fijo para el asistente IA Freemium
B29: API Claude Sonnet por cliente activo | C29: 0.37 | D29: Costo de procesamiento mensual del Gemelo Digital
B31: 4. PARÁMETROS LEGALES DE PERSONAL Y SALARIOS
B32: Esquema de Pagas Ordinarias (12 o 14) | C32: 12 | D32: Pagas mensuales (12 o 14 pagas reguladas por convenio)
B33: Seguridad Social a Cargo de la Empresa (%) | C33: 0.321 | D33: Carga patronal (CC, Desempleo, FOGASA, Accidentes, MEEI) | E33: Cuota RETA General | F33: 448.69
B34: Seguridad Social a Cargo del Empleado (%) | C34: 0.0647 | D34: Deducción de nómina al trabajador (CC, FP, MEEI) | E34: Cuota RETA Tarifa Plana | F34: 88.56
B35: Base Máxima de Cotización Mensual (Tope) | C35: 4720.5 | D35: Tope de cotización para salarios altos en España
B36: Base Mínima de Cotización SMI Mensual | C36: 1300 | D36: Salario Mínimo Interprofesional base
B38: Puesto / Rol | C38: Salario Bruto Anual | D38: Mes Inicio | E38: IRPF Estimado %
B39: CEO (Socio Fundador) | C39: 18000 | D39: 1 | E39: 0.15
B40: CTO (Socio Fundador) | C40: 18000 | D40: 1 | E40: 0.15
B41: CMO (Socio Fundador) | C41: 18000 | D41: 1 | E41: 0.15
B42: COO (Socio Fundador) | C42: 18000 | D42: 1 | E42: 0.15
B43: Senior Software & Cloud Eng. | C43: 45000 | D43: 13 | E43: 0.15
B44: Customer Success Specialist | C44: 24000 | D44: 13 | E44: 0.14
B45: Sales & Marketing B2B Spec. | C45: 30000 | D45: 13 | E45: 0.15
...

Sheet 2_AJUSTES_MACRO
B2: CONFIGURACIÓN GENERAL (MACRO) | E2: Escenario Activo: | F2: =CHOOSE('1_PANEL_CONTROL'!$C$4, "🔴 1: NEGATIVO", "🟡 2: EQUILIBRIO", "🟢 3: POSITIVO") -> 🟡 2: EQUILIBRIO
B3: =CHOOSE('1_PANEL_CONTROL'!$C$4, "[NEGATIVO] VARIABLES MACRO DE AJUSTE. Se aplica 21% de impuestos y 11,79% WACC. En este escenario adverso de menor liquidez, controlar la caja es crítico.", "[EQUILIBRIO] VARIABLES MACRO DE AJUSTE. Estructura de capital híbrido (WACC 11,79%). Caja inicial recomendada de " & TEXT('13_CAP_TABLE_FINANCIACION'!C15, "#.##0 €") & " con apoyo ENISA.", "[POSITIVO] VARIABLES MACRO DE AJUSTE. Estructura de Venture Capital (WACC 11,79%). Caja inicial óptima de " & TEXT('13_CAP_TABLE_FINANCIACION'!C15, "#.##0 €") & " para desarrollo intensivo.") -> [EQUILIBRIO] VARIABLES MACRO DE AJUSTE. Estructura de capital híbrido (WACC 11,79%). Caja inicial recomendada de 215.000 € con apoyo ENISA.
B4: Valor Terminal de Salida | C4: ='1_PANEL_CONTROL'!$C$9 -> 42000000 | D4: Valor terminal estimado para valoración de salida
B5: Tasa de Descuento (WACC) | C5: ='1_PANEL_CONTROL'!$C$8 -> 0.1179 | D5: Tasa de descuento de flujos de caja
B6: Tasa Impositiva (Sociedades) | C6: ='1_PANEL_CONTROL'!$C$7 -> 0.21 | D6: Tasa de impuesto sobre sociedades en España
B7: Inicio Año Fiscal (Mes) | C7: 1 | D7: Mes de inicio del año fiscal (Enero = 1)
B8: Reserva Mínima de Caja | C8: ='1_PANEL_CONTROL'!$C$11 -> 500 | D8: Reserva de seguridad mínima en caja
B9: Tasa de Inflación Anual | C9: ='1_PANEL_CONTROL'!$C$12 -> 0.03 | D9: Tasa de inflación anual proyectada
B12: PERIODOS DE AMORTIZACIÓN DE CAPEX
B14: Equipos Informáticos / Hardware | C14: ='1_PANEL_CONTROL'!$C$10/12 -> 5 | D14: Años | Amortización de ordenadores en años
B15: Reforma de Oficina / Coworking | C15: 5 | D15: Años | 20.0% anual
B16: Mobiliario y Enseres | C16: 5 | D16: Años | 20.0% anual
B17: Telecomunicaciones | C17: 3 | D17: Años | 33.3% anual
B18: Infraestructura de Servidores & Apps | C18: ='1_PANEL_CONTROL'!$C$10/12 -> 5 | D18: Años | Desarrollo plataforma CUDI
B20: GUÍA DE CONFIGURACIÓN MACROECONÓMICA Y PARÁMETROS FISCALES
B21: 1. SUPUESTOS MACRO Y FISCALES: - IPC / Ajuste Salarial: Aplicado un 3.50% de ajuste por inflación en Años 2 y 3 para la masa salarial. - Impuesto de Sociedades: Modelado al 21.00% según la legislación vigente en España para startups. - RETA (Autónomos): Tarifa plana de 88,56 €/mes en Año 1 para cofundadores, escalando a cuota regular en Año 2. - Seguridad Social Empresa: 32.10% para el personal contratado por cuenta ajena (Régimen General). 2. TASA DE DESCUENTO E INVERSIÓN: - WACC de Descuento: Fijado en 11.79% para el cálculo de VAN/TIR, ponderando el coste de deuda y equity.

Sheet 3_HIPOTESIS_NEGOCIO
B2: SUPUESTOS OPERATIVOS DEL NEGOCIO (ESCENARIO ACTIVO) | E2: Escenario Activo: | F2: =CHOOSE('1_PANEL_CONTROL'!$C$4, "🔴 1: NEGATIVO", "🟡 2: EQUILIBRIO", "🟢 3: POSITIVO") -> 🟡 2: EQUILIBRIO
B3: =CHOOSE('1_PANEL_CONTROL'!$C$4, "[NEGATIVO] SUPUESTOS OPERATIVOS DEL NEGOCIO. Tasas activas del escenario. Churn elevado del " & TEXT('3_HIPOTESIS_NEGOCIO'!C6, "0,0%") & " y coste de captación CPL de " & TEXT('3_HIPOTESIS_NEGOCIO'!C20, "0,00 €") & " dificultan la rentabilidad.", "[EQUILIBRIO] SUPUESTOS OPERATIVOS DEL NEGOCIO. Tasas activas del escenario. Churn moderado del " & TEXT('3_HIPOTESIS_NEGOCIO'!C6, "0,0%") & " y CPL de " & TEXT('3_HIPOTESIS_NEGOCIO'!C20, "0,00 €") & " para el break-even.", "[POSITIVO] SUPUESTOS OPERATIVOS DEL NEGOCIO. Tasas activas del escenario. Tracción muy alta con churn del " & TEXT('3_HIPOTESIS_NEGOCIO'!C6, "0,0%") & " y CPL de " & TEXT('3_HIPOTESIS_NEGOCIO'!C20, "0,00 €") & " (alta eficiencia de Ads).") -> [EQUILIBRIO] SUPUESTOS OPERATIVOS DEL NEGOCIO. Tasas activas del escenario. Churn moderado del 4,8% y CPL de 11,00 € para el break-even.
B4: Tasa Conversión (Visita a Premium) | C4: ='4_PROY_DEMANDA'!$D$73 -> 0.02 | D4: Tasa de conversión en el escenario activo
B5: Precio Premium Care CUDI (SaaS) | C5: ='1_PANEL_CONTROL'!$C$15 -> 30 | D5: Membresía recurrente mensual del plan Premium Care
B6: Tasa Cancelación Mensual (Churn) | C6: ='4_PROY_DEMANDA'!$D$80 -> 0.048 | D6: Tasa de bajas del plan Premium Care
B7: CAC Teórico (Lead Orgánico) | C7: 5 | D7: Costo implícito de adquisición orgánico (SEO y RRSS)
B8: Tráfico Orgánico Inicial (Mes 1) | C8: ='4_PROY_DEMANDA'!$D$72 -> 2027 | D8: Tráfico inicial mensual orgánico de la web
B9: Crecimiento Tráfico Orgánico Mensual | C9: ='4_PROY_DEMANDA'!$D$71 -> 0.08 | D9: Tasa de crecimiento mensual del tráfico orgánico
B10: Tasa Adhesión CUDI Shield Basic | C10: ='4_PROY_DEMANDA'!$D$82 -> 0.3 | D10: Porcentaje de adhesión del seguro CUDI Shield
B11: Precio CUDI Shield Basic (Seguro) | C11: ='1_PANEL_CONTROL'!$C$17 -> 18 | D11: Mensualidad del Seguro CUDI Shield
B12: Tasa Visitas VetHome Mensuales | C12: ='4_PROY_DEMANDA'!$D$85 -> 0.045 | D12: Tasa mensual de visitas VetHome por usuario Premium
B13: Precio Visita VetHome CUDI | C13: ='1_PANEL_CONTROL'!$C$18 -> 75 | D13: Precio cobrado por visita veterinaria a domicilio
B14: Tasa Compras en Marketplace | C14: ='4_PROY_DEMANDA'!$D$87 -> 0.2 | D14: Porcentaje de compras de la base Premium en marketplace
B15: Comisión Media Marketplace | C15: ='1_PANEL_CONTROL'!$C$21 -> 3.75 | D15: Comisión neta promedio ganada por transacción
B16: Mes Inicio Pauta Publicitaria | C16: 1 | D16: Mes en que se inicia la captación de pago (Ene-26 = 1)
B17: Presupuesto Publicitario Social Ads | C17: ='1_PANEL_CONTROL'!$C$80 -> 2000 | D17: Presupuesto plano constante de Meta/TikTok Ads
B18: Incremento Mensual del Presupuesto | C18: 0 | D18: Estrategia de inversión plana (no incremental)
B19: Presupuesto Publicitario Máximo | C19: ='1_PANEL_CONTROL'!$C$80 -> 2000 | D19: Techo de la inversión publicitaria mensual
B20: Coste por Lead de Pago (CPL) | C20: ='4_PROY_DEMANDA'!$D$76 -> 11 | D20: Coste de captación del lead publicitario
B21: Coste Servidor AWS por cliente activo | C21: ='1_PANEL_CONTROL'!$C$26 -> 0.6 | D21: Costo mensual de base de datos e IoT por cliente activo
B22: Comisión Pasarela Pago (Stripe %) | C22: ='1_PANEL_CONTROL'!$C$27 -> 0.025 | D22: Comisión Stripe por procesamiento de cobros
B23: Tarifa Fija API Gemini Flash | C23: ='1_PANEL_CONTROL'!$C$28 -> 100 | D23: Coste de la suite de chat de asistencia Freemium
B24: API Claude Sonnet por usuario | C24: ='1_PANEL_CONTROL'!$C$29 -> 0.37 | D24: Coste de API mensual del Gemelo Digital
B25: Coste Fabricación Smart Collar | C25: ='1_PANEL_CONTROL'!$C$24 -> 35 | D25: Costo unitario de fabricación del hardware
B26: Coste de Mensajería Última Milla | C26: ='1_PANEL_CONTROL'!$C$25 -> 6.5 | D26: Costo de envío urgente nacional del collar a domicilio
B28: ESTRATEGIA GLOBAL DE MARKETING (TFM CUDI 2026) - ENFOQUE ADQUISICIÓN Y RETENCIÓN B2C/B2B
B29: La estrategia global de marketing de CUDI se basa en un modelo Inbound Omnicanal con fuerte enfoque en coste de adquisición de cliente (CAC) controlado y posicionamiento de marca de confianza (E-E-A-T): 1. ADQUISICIÓN ORGÁNICA (EEAT SEO & CONTENIDOS): Se destina un redactor médico veterinario dedicado para generar contenidos de salud, comportamiento y nutrición animal avalados profesionalmente. Esto posiciona a CUDI en buscadores para keywords transaccionales locales de Barcelona, atrayendo tráfico de alta intención a coste marginal cero. 2. ALIANZAS CON LA RED DE SOCIOS B2B: Se establece una red de clínicas veterinarias, peluquerías caninas, paseadores y guarderías de confianza en Barcelona. CUDI distribuye welcome packs físicos a través de estos partners, quienes prescriben la suscripción Premium Care y el collar GPS en sus locales a cambio de comisiones (take-rate). 3. PAUTA PUBLICITARIA DIGITAL (PERFORMANCE ADS): Estrategia plana 'Always-on' de 2.000 €/mes en Meta Ads (Instagram/Facebook) y TikTok Ads. Se divide el funnel en: Fase de Branding (Creatividades fijas e historias de éxito), Fase de Captación de Leads (Descarga de e-books de salud canina), y Fase de Remarketing (BOFU retargeting con cupones de descuento del Smart Collar) para maximizar la conversión. 4. EVENTOS Y MARKETING DE GUERRILLA B2B/B2C: Presencia en ferias y congresos clave del sector pet-tech y veterinario (como Iberzoo+Propet en IFEMA y el Congreso AVEPA-SEVC en el CCIB de Barcelona) mediante stands modulares diseñados para captar distribuidores y clínicas asociadas a gran escala. 5. AUTOMATIZACIÓN INBOUND CRM (HUBSPOT): Nutrición automatizada de leads (lead nurturing) mediante correos electrónicos segmentados por tipo de mascota, edad y nivel de actividad, forzando la conversión recurrente a Premium.
B37: GUÍA DE HIPÓTESIS DE NEGOCIO Y CONVERSIÓN
B38: 1. HIPÓTESIS DE ADQUISICIÓN Y MARKETING: - Crecimiento Tráfico Orgánico: Inicia en 1.000 visitas/mes y crece del 5% al 15% según el escenario activo. - Coste por Lead (CPL) y Ads: Presupuesto publicitario plano de 2.000 €/mes con CPL variable por escenario (7 € a 15 €). - Conversión Web: Se asume que el 2.00% del tráfico general se convierte en Lead Calificado. 2. RETENCIÓN Y VIDA ÚTIL (LTV): - Tasa de Churn Mensual: Factor crítico de retención, calibrado en 4.80% para el escenario de Equilibrio. - Vida Útil Media (Lifetime): Calculada como 1 / Churn Rate, equivaliendo a 20.83 meses de retención en Equilibrio.

Sheet 4_PROY_DEMANDA
A4: PROYECCIONES DE DEMANDA POR ESCENARIO (84 MESES) | E4: Escenario Activo: | F4: =CHOOSE('1_PANEL_CONTROL'!$C$4, "🔴 1: NEGATIVO", "🟡 2: EQUILIBRIO", "🟢 3: POSITIVO") -> 🟡 2: EQUILIBRIO
A5: =CHOOSE('1_PANEL_CONTROL'!$C$4, "[NEGATIVO] PROYECCIÓN DE DEMANDA MENSUAL. En el mes 12 alcanzamos solo " & TEXT('4_PROY_DEMANDA'!O21, "#.##0") & " usuarios activos en Premium Care, generando un total de " & TEXT('4_PROY_DEMANDA'!O23, "#.##0") & " clientes en seguros Shield.", "[EQUILIBRIO] PROYECCIÓN DE DEMANDA MENSUAL. En el mes 12 alcanzamos el hito de " & TEXT('4_PROY_DEMANDA'!O41, "#.##0") & " usuarios Premium Care y " & TEXT('4_PROY_DEMANDA'!O43, "#.##0") & " asegurados.", "[POSITIVO] PROYECCIÓN DE DEMANDA MENSUAL. En el mes 12 logramos los " & TEXT('4_PROY_DEMANDA'!O61, "#.##0") & " usuarios activos y vendemos " & TEXT(SUM('4_PROY_DEMANDA'!D64:O64), "#.##0") & " Smart Collars en Año 1.") -> [EQUILIBRIO] PROYECCIÓN DE DEMANDA MENSUAL. En el mes 12 alcanzamos el hito de 670 usuarios Premium Care y 201 asegurados.
A8: Métrica de Demanda | B8: Unidad | C8: Escenario / Regla | D8: Ene-26 | E8: Feb-26 | F8: Mar-26 | G8: Abr-26 | H8: May-26 | I8: Jun-26 | J8: Jul-26 | K8: Ago-26 | L8: Sep-26 | M8: Oct-26 | N8: Nov-26 | O8: Dic-26 | P8: Ene-27 | Q8: Feb-27 | R8: Mar-27 | S8: Abr-27 | T8: May-27 | U8: Jun-27 | V8: Jul-27 | W8: Ago-27 | X8: Sep-27 | Y8: Oct-27 | Z8: Nov-27 | AA8: Dic-27 | AB8: Ene-28 | AC8: Feb-28 | AD8: Mar-28 | AE8: Abr-28 | AF8: May-28 | AG8: Jun-28 | AH8: Jul-28 | AI8: Ago-28 | AJ8: Sep-28 | AK8: Oct-28 | AL8: Nov-28 | AM8: Dic-28 | AN8: Ene-29 | AO8: Feb-29 | AP8: Mar-29 | AQ8: Abr-29 | AR8: May-29 | AS8: Jun-29 | AT8: Jul-29 | AU8: Ago-29 | AV8: Sep-29 | AW8: Oct-29 | AX8: Nov-29 | AY8: Dic-29 | AZ8: Ene-30 | BA8: Feb-30 | BB8: Mar-30 | BC8: Abr-30 | BD8: May-30 | BE8: Jun-30 | BF8: Jul-30 | BG8: Ago-30 | BH8: Sep-30 | BI8: Oct-30 | BJ8: Nov-30 | BK8: Dic-30 | BL8: Ene-31 | BM8: Feb-31 | BN8: Mar-31 | BO8: Abr-31 | BP8: May-31 | BQ8: Jun-31 | BR8: Jul-31 | BS8: Ago-31 | BT8: Sep-31 | BU8: Oct-31 | BV8: Nov-31 | BW8: Dic-31 | BX8: Ene-32 | BY8: Feb-32 | BZ8: Mar-32 | CA8: Abr-32 | CB8: May-32 | CC8: Jun-32 | CD8: Jul-32 | CE8: Ago-32 | CF8: Sep-32 | CG8: Oct-32 | CH8: Nov-32 | CI8: Dic-32
A10: ESCENARIO 1: NEGATIVO
A11: Crecimiento Tráfico Orgánico | B11: % | C11: 0.05 | D11: 0.05 | E11: 0.05 | F11: 0.05 | G11: 0.05 | H11: 0.05 | I11: 0.05 | J11: 0.05 | K11: 0.05 | L11: 0.05 | M11: 0.05 | N11: 0.05 | O11: 0.05 | P11: 0.05 | Q11: 0.05 | R11: 0.05 | S11: 0.05 | T11: 0.05 | U11: 0.05 | V11: 0.05 | W11: 0.05 | X11: 0.05 | Y11: 0.05 | Z11: 0.05 | AA11: 0.05 | AB11: 0.05 | AC11: 0.05 | AD11: 0.05 | AE11: 0.05 | AF11: 0.05 | AG11: 0.05 | AH11: 0.05 | AI11: 0.05 | AJ11: 0.05 | AK11: 0.05 | AL11: 0.05 | AM11: 0.05 | AN11: 0.05 | AO11: 0.05 | AP11: 0.05 | AQ11: 0.05 | AR11: 0.05 | AS11: 0.05 | AT11: 0.05 | AU11: 0.05 | AV11: 0.05 | AW11: 0.05 | AX11: 0.05 | AY11: 0.05 | AZ11: 0.05 | BA11: 0.05 | BB11: 0.05 | BC11: 0.05 | BD11: 0.05 | BE11: 0.05 | BF11: 0.05 | BG11: 0.05 | BH11: 0.05 | BI11: 0.05 | BJ11: 0.05 | BK11: 0.05 | BL11: 0.05 | BM11: 0.05 | BN11: 0.05 | BO11: 0.05 | BP11: 0.05 | BQ11: 0.05 | BR11: 0.05 | BS11: 0.05 | BT11: 0.05 | BU11: 0.05 | BV11: 0.05 | BW11: 0.05 | BX11: 0.05 | BY11: 0.05 | BZ11: 0.05 | CA11: 0.05 | CB11: 0.05 | CC11: 0.05 | CD11: 0.05 | CE11: 0.05 | CF11: 0.05 | CG11: 0.05 | CH11: 0.05 | CI11: 0.05
A12: Tráfico Orgánico Mensual | B12: # | C12: M1=1000, Mt=Prev*(1+Growth) | D12: 1000 | E12: =D12*(1+E11) -> 1050 | F12: =E12*(1+F11) -> 1102.5 | G12: =F12*(1+G11) -> 1157.625 | H12: =G12*(1+H11) -> 1215.5063 | I12: =H12*(1+I11) -> 1276.2816 | J12: =I12*(1+J11) -> 1340.0956 | K12: =J12*(1+K11) -> 1407.1004 | L12: =K12*(1+L11) -> 1477.4554 | ... CI12: =CH12*(1+CI11) -> 57373.563
A13: Tasa de Conversión | B13: % | C13: 0.0213 | D13: 0.0213 | E13: 0.0213 | F13: 0.0213 | G13: 0.0213 | H13: 0.0213 | I13: 0.0213 | J13: 0.0213 | K13: 0.0213 | L13: 0.0213 | M13: 0.0213 | N13: 0.0213 | O13: 0.0213 | P13: 0.0213 | Q13: 0.0213 | R13: 0.0213 | S13: 0.0213 | T13: 0.0213 | U13: 0.0213 | V13: 0.0213 | W13: 0.0213 | X13: 0.0213 | Y13: 0.0213 | Z13: 0.0213 | AA13: 0.0213 | AB13: 0.0213 | AC13: 0.0213 | AD13: 0.0213 | AE13: 0.0213 | AF13: 0.0213 | AG13: 0.0213 | AH13: 0.0213 | AI13: 0.0213 | AJ13: 0.0213 | AK13: 0.0213 | AL13: 0.0213 | AM13: 0.0213 | AN13: 0.0213 | AO13: 0.0213 | AP13: 0.0213 | AQ13: 0.0213 | AR13: 0.0213 | AS13: 0.0213 | AT13: 0.0213 | AU13: 0.0213 | AV13: 0.0213 | AW13: 0.0213 | AX13: 0.0213 | AY13: 0.0213 | AZ13: 0.0213 | BA13: 0.0213 | BB13: 0.0213 | BC13: 0.0213 | BD13: 0.0213 | BE13: 0.0213 | BF13: 0.0213 | BG13: 0.0213 | BH13: 0.0213 | BI13: 0.0213 | BJ13: 0.0213 | BK13: 0.0213 | BL13: 0.0213 | BM13: 0.0213 | BN13: 0.0213 | BO13: 0.0213 | BP13: 0.0213 | BQ13: 0.0213 | BR13: 0.0213 | BS13: 0.0213 | BT13: 0.0213 | BU13: 0.0213 | BV13: 0.0213 | BW13: 0.0213 | BX13: 0.0213 | BY13: 0.0213 | BZ13: 0.0213 | CA13: 0.0213 | CB13: 0.0213 | CC13: 0.0213 | CD13: 0.0213 | CE13: 0.0213 | CF13: 0.0213 | CG13: 0.0213 | CH13: 0.0213 | CI13: 0.0213
A14: Nuevos Clientes (Orgánicos) | B14: # | C14: ROUND(Tráfico*Conversión, 0) | D14: =ROUND(D12*D13, 0) -> 21 | E14: =ROUND(E12*E13, 0) -> 22 | F14: =ROUND(F12*F13, 0) -> 23 | G14: =ROUND(G12*G13, 0) -> 25 | H14: =ROUND(H12*H13, 0) -> 26 | I14: =ROUND(I12*I13, 0) -> 27 | J14: =ROUND(J12*J13, 0) -> 29 | K14: =ROUND(K12*K13, 0) -> 30 | ... CI14: =ROUND(CI12*CI13, 0) -> 1222
A15: Presupuesto Social Ads | B15: EUR | C15: '1_PANEL_CONTROL'!$C$80 | D15: ='1_PANEL_CONTROL'!$C$80+'1_PANEL_CONTROL'!$C$69+'1_PANEL_CONTROL'!$C$68 -> 2955 | E15: ='1_PANEL_CONTROL'!$C$80+'1_PANEL_CONTROL'!$C$69+'1_PANEL_CONTROL'!$C$68 -> 2955 | F15: ='1_PANEL_CONTROL'!$C$80+'1_PANEL_CONTROL'!$C$69+'1_PANEL_CONTROL'!$C$68 -> 2955 | G15: ='1_PANEL_CONTROL'!$C$80+'1_PANEL_CONTROL'!$C$69+'1_PANEL_CONTROL'!$C$68 -> 2955 | H15: ='1_PANEL_CONTROL'!$C$80+'1_PANEL_CONTROL'!$C$69+'1_PANEL_CONTROL'!$C$68 -> 2955 | I15: ='1_PANEL_CONTROL'!$C$80+'1_PANEL_CONTROL'!$C$69+'1_PANEL_CONTROL'!$C$68 -> 2955 | J15: ='1_PANEL_CONTROL'!$C$80+'1_PANEL_CONTROL'!$C$69+'1_PANEL_CONTROL'!$C$68 -> 2955 | K15: ='1_PANEL_CONTROL'!$C$80+'1_PANEL_CONTROL'!$C$69+'1_PANEL_CONTROL'!$C$68 -> 2955 | ... CI15: ='1_PANEL_CONTROL'!$C$80+'1_PANEL_CONTROL'!$C$69+'1_PANEL_CONTROL'!$C$68 -> 2955
A16: CPL Paid (Coste por Lead) | B16: EUR | C16: 15.0 | D16: 15 | E16: 15 | F16: 15 | G16: 15 | H16: 15 | I16: 15 | J16: 15 | K16: 15 | L16: 15 | M16: 15 | N16: 15 | O16: 15 | P16: 15 | Q16: 15 | R16: 15 | S16: 15 | T16: 15 | U16: 15 | V16: 15 | W16: 15 | X16: 15 | Y16: 15 | Z16: 15 | AA16: 15 | AB16: 15 | AC16: 15 | AD16: 15 | AE16: 15 | AF16: 15 | AG16: 15 | AH16: 15 | AI16: 15 | AJ16: 15 | AK16: 15 | AL16: 15 | AM16: 15 | AN16: 15 | AO16: 15 | AP16: 15 | AQ16: 15 | AR16: 15 | AS16: 15 | AT16: 15 | AU16: 15 | AV16: 15 | AW16: 15 | AX16: 15 | AY16: 15 | AZ16: 15 | BA16: 15 | BB16: 15 | BC16: 15 | BD16: 15 | BE16: 15 | BF16: 15 | BG16: 15 | BH16: 15 | BI16: 15 | BJ16: 15 | BK16: 15 | BL16: 15 | BM16: 15 | BN16: 15 | BO16: 15 | BP16: 15 | BQ16: 15 | BR16: 15 | BS16: 15 | BT16: 15 | BU16: 15 | BV16: 15 | BW16: 15 | BX16: 15 | BY16: 15 | BZ16: 15 | CA16: 15 | CB16: 15 | CC16: 15 | CD16: 15 | CE16: 15 | CF16: 15 | CG16: 15 | CH16: 15 | CI16: 15
A17: Leads de Pago Adquiridos | B17: # | C17: ROUND(Presupuesto/CPL, 0) | D17: =ROUND(D15/D16, 0) -> 197 | E17: =ROUND(E15/E16, 0) -> 197 | F17: =ROUND(F15/F16, 0) -> 197 | G17: =ROUND(G15/G16, 0) -> 197 | H17: =ROUND(H15/H16, 0) -> 197 | I17: =ROUND(I15/I16, 0) -> 197 | J17: =ROUND(J15/J16, 0) -> 197 | K17: =ROUND(K15/K16, 0) -> 197 | ... CI17: =ROUND(CI15/CI16, 0) -> 197
A18: Nuevos Clientes (Pauta/Paid) | B18: # | C18: ROUND(Leads*Conversión, 0) | D18: =ROUND(D17*D13, 0) -> 4 | E18: =ROUND(E17*E13, 0) -> 4 | F18: =ROUND(F17*F13, 0) -> 4 | G18: =ROUND(G17*G13, 0) -> 4 | H18: =ROUND(H17*H13, 0) -> 4 | I18: =ROUND(I17*I13, 0) -> 4 | J18: =ROUND(J17*J13, 0) -> 4 | K18: =ROUND(K17*K13, 0) -> 4 | ... CI18: =ROUND(CI17*CI13, 0) -> 4
A19: Nuevos Clientes Totales | B19: # | C19: Orgánicos + Paid | D19: =D14+D18 -> 25 | E19: =E14+E18 -> 26 | F19: =F14+F18 -> 27 | G19: =G14+G18 -> 29 | H19: =H14+H18 -> 30 | I19: =I14+I18 -> 31 | J19: =J14+J18 -> 33 | K19: =K14+K18 -> 34 | ... CI19: =CI14+CI18 -> 1226
A20: Tasa Cancelación (Churn) | B20: % | C20: 0.08 | D20: 0.08 | E20: 0.08 | F20: 0.08 | G20: 0.08 | H20: 0.08 | I20: 0.08 | J20: 0.08 | K20: 0.08 | L20: 0.08 | M20: 0.08 | N20: 0.08 | O20: 0.08 | P20: 0.08 | Q20: 0.08 | R20: 0.08 | S20: 0.08 | T20: 0.08 | U20: 0.08 | V20: 0.08 | W20: 0.08 | X20: 0.08 | Y20: 0.08 | Z20: 0.08 | AA20: 0.08 | AB20: 0.08 | AC20: 0.08 | AD20: 0.08 | AE20: 0.08 | AF20: 0.08 | AG20: 0.08 | AH20: 0.08 | AI20: 0.08 | AJ20: 0.08 | AK20: 0.08 | AL20: 0.08 | AM20: 0.08 | AN20: 0.08 | AO20: 0.08 | AP20: 0.08 | AQ20: 0.08 | AR20: 0.08 | AS20: 0.08 | AT20: 0.08 | AU20: 0.08 | AV20: 0.08 | AW20: 0.08 | AX20: 0.08 | AY20: 0.08 | AZ20: 0.08 | BA20: 0.08 | BB20: 0.08 | BC20: 0.08 | BD20: 0.08 | BE20: 0.08 | BF20: 0.08 | BG20: 0.08 | BH20: 0.08 | BI20: 0.08 | BJ20: 0.08 | BK20: 0.08 | BL20: 0.08 | BM20: 0.08 | BN20: 0.08 | BO20: 0.08 | BP20: 0.08 | BQ20: 0.08 | BR20: 0.08 | BS20: 0.08 | BT20: 0.08 | BU20: 0.08 | BV20: 0.08 | BW20: 0.08 | BX20: 0.08 | BY20: 0.08 | BZ20: 0.08 | CA20: 0.08 | CB20: 0.08 | CC20: 0.08 | CD20: 0.08 | CE20: 0.08 | CF20: 0.08 | CG20: 0.08 | CH20: 0.08 | CI20: 0.08
A21: Clientes Activos (Premium Care) | B21: # | C21: M1=Nuevos, Mt=ROUND(Prev*(1-Churn)+Nuevos, 0) | D21: =D19 -> 25 | E21: =ROUND(D21*(1-E20)+E19, 0) -> 49 | F21: =ROUND(E21*(1-F20)+F19, 0) -> 72 | G21: =ROUND(F21*(1-G20)+G19, 0) -> 95 | H21: =ROUND(G21*(1-H20)+H19, 0) -> 117 | I21: =ROUND(H21*(1-I20)+I19, 0) -> 139 | J21: =ROUND(I21*(1-J20)+J19, 0) -> 161 | K21: =ROUND(J21*(1-K20)+K19, 0) -> 182 | L21: =ROUND(K21*(1-L20)+L19, 0) -> 202 | ... CI21: =ROUND(CH21*(1-CI20)+CI19, 0) -> 9919
A22: Attachment CUDI Shield Basic | B22: % | C22: 0.15 | D22: 0.15 | E22: 0.15 | F22: 0.15 | G22: 0.15 | H22: 0.15 | I22: 0.15 | J22: 0.15 | K22: 0.15 | L22: 0.15 | M22: 0.15 | N22: 0.15 | O22: 0.15 | P22: 0.15 | Q22: 0.15 | R22: 0.15 | S22: 0.15 | T22: 0.15 | U22: 0.15 | V22: 0.15 | W22: 0.15 | X22: 0.15 | Y22: 0.15 | Z22: 0.15 | AA22: 0.15 | AB22: 0.15 | AC22: 0.15 | AD22: 0.15 | AE22: 0.15 | AF22: 0.15 | AG22: 0.15 | AH22: 0.15 | AI22: 0.15 | AJ22: 0.15 | AK22: 0.15 | AL22: 0.15 | AM22: 0.15 | AN22: 0.15 | AO22: 0.15 | AP22: 0.15 | AQ22: 0.15 | AR22: 0.15 | AS22: 0.15 | AT22: 0.15 | AU22: 0.15 | AV22: 0.15 | AW22: 0.15 | AX22: 0.15 | AY22: 0.15 | AZ22: 0.15 | BA22: 0.15 | BB22: 0.15 | BC22: 0.15 | BD22: 0.15 | BE22: 0.15 | BF22: 0.15 | BG22: 0.15 | BH22: 0.15 | BI22: 0.15 | BJ22: 0.15 | BK22: 0.15 | BL22: 0.15 | BM22: 0.15 | BN22: 0.15 | BO22: 0.15 | BP22: 0.15 | BQ22: 0.15 | BR22: 0.15 | BS22: 0.15 | BT22: 0.15 | BU22: 0.15 | BV22: 0.15 | BW22: 0.15 | BX22: 0.15 | BY22: 0.15 | BZ22: 0.15 | CA22: 0.15 | CB22: 0.15 | CC22: 0.15 | CD22: 0.15 | CE22: 0.15 | CF22: 0.15 | CG22: 0.15 | CH22: 0.15 | CI22: 0.15
A23: Clientes Activos Shield Seguro | B23: # | C23: ROUND(Premium_Activos*Attachment, 0) | D23: =ROUND(D21*D22, 0) -> 4 | E23: =ROUND(E21*E22, 0) -> 7 | F23: =ROUND(F21*F22, 0) -> 11 | G23: =ROUND(G21*G22, 0) -> 14 | H23: =ROUND(H21*H22, 0) -> 18 | I23: =ROUND(I21*I22, 0) -> 21 | J23: =ROUND(J21*J22, 0) -> 24 | K23: =ROUND(K21*K22, 0) -> 27 | ... CI23: =ROUND(CI21*CI22, 0) -> 1488
A24: Smart Collars Vendidos | B24: # | C24: Nuevos Clientes Totales | D24: =D19 -> 25 | E24: =E19 -> 26 | F24: =F19 -> 27 | G24: =G19 -> 29 | H24: =H19 -> 30 | I24: =I19 -> 31 | J24: =J19 -> 33 | K24: =K19 -> 34 | ... CI24: =CI19 -> 1226
A25: Tasa Visitas VetHome | B25: % | C25: 0.02 | D25: 0.02 | E25: 0.02 | F25: 0.02 | G25: 0.02 | H25: 0.02 | I25: 0.02 | J25: 0.02 | K25: 0.02 | L25: 0.02 | M25: 0.02 | N25: 0.02 | O25: 0.02 | P25: 0.02 | Q25: 0.02 | R25: 0.02 | S25: 0.02 | T25: 0.02 | U25: 0.02 | V25: 0.02 | W25: 0.02 | X25: 0.02 | Y25: 0.02 | Z25: 0.02 | AA25: 0.02 | AB25: 0.02 | AC25: 0.02 | AD25: 0.02 | AE25: 0.02 | AF25: 0.02 | AG25: 0.02 | AH25: 0.02 | AI25: 0.02 | AJ25: 0.02 | AK25: 0.02 | AL25: 0.02 | AM25: 0.02 | AN25: 0.02 | AO25: 0.02 | AP25: 0.02 | AQ25: 0.02 | AR25: 0.02 | AS25: 0.02 | AT25: 0.02 | AU25: 0.02 | AV25: 0.02 | AW25: 0.02 | AX25: 0.02 | AY25: 0.02 | AZ25: 0.02 | BA25: 0.02 | BB25: 0.02 | BC25: 0.02 | BD25: 0.02 | BE25: 0.02 | BF25: 0.02 | BG25: 0.02 | BH25: 0.02 | BI25: 0.02 | BJ25: 0.02 | BK25: 0.02 | BL25: 0.02 | BM25: 0.02 | BN25: 0.02 | BO25: 0.02 | BP25: 0.02 | BQ25: 0.02 | BR25: 0.02 | BS25: 0.02 | BT25: 0.02 | BU25: 0.02 | BV25: 0.02 | BW25: 0.02 | BX25: 0.02 | BY25: 0.02 | BZ25: 0.02 | CA25: 0.02 | CB25: 0.02 | CC25: 0.02 | CD25: 0.02 | CE25: 0.02 | CF25: 0.02 | CG25: 0.02 | CH25: 0.02 | CI25: 0.02
A26: Visitas VetHome Proyectadas | B26: # | C26: ROUND(Premium_Activos*VetHome_Rate, 0) | D26: =ROUND(D21*D25, 0) -> 1 | E26: =ROUND(E21*E25, 0) -> 1 | F26: =ROUND(F21*F25, 0) -> 1 | G26: =ROUND(G21*G25, 0) -> 2 | H26: =ROUND(H21*H25, 0) -> 2 | I26: =ROUND(I21*I25, 0) -> 3 | J26: =ROUND(J21*J25, 0) -> 3 | K26: =ROUND(K21*K25, 0) -> 4 | ... CI26: =ROUND(CI21*CI25, 0) -> 198
A27: Tasa Compras Marketplace | B27: % | C27: 0.05 | D27: 0.05 | E27: 0.05 | F27: 0.05 | G27: 0.05 | H27: 0.05 | I27: 0.05 | J27: 0.05 | K27: 0.05 | L27: 0.05 | M27: 0.05 | N27: 0.05 | O27: 0.05 | P27: 0.05 | Q27: 0.05 | R27: 0.05 | S27: 0.05 | T27: 0.05 | U27: 0.05 | V27: 0.05 | W27: 0.05 | X27: 0.05 | Y27: 0.05 | Z27: 0.05 | AA27: 0.05 | AB27: 0.05 | AC27: 0.05 | AD27: 0.05 | AE27: 0.05 | AF27: 0.05 | AG27: 0.05 | AH27: 0.05 | AI27: 0.05 | AJ27: 0.05 | AK27: 0.05 | AL27: 0.05 | AM27: 0.05 | AN27: 0.05 | AO27: 0.05 | AP27: 0.05 | AQ27: 0.05 | AR27: 0.05 | AS27: 0.05 | AT27: 0.05 | AU27: 0.05 | AV27: 0.05 | AW27: 0.05 | AX27: 0.05 | AY27: 0.05 | AZ27: 0.05 | BA27: 0.05 | BB27: 0.05 | BC27: 0.05 | BD27: 0.05 | BE27: 0.05 | BF27: 0.05 | BG27: 0.05 | BH27: 0.05 | BI27: 0.05 | BJ27: 0.05 | BK27: 0.05 | BL27: 0.05 | BM27: 0.05 | BN27: 0.05 | BO27: 0.05 | BP27: 0.05 | BQ27: 0.05 | BR27: 0.05 | BS27: 0.05 | BT27: 0.05 | BU27: 0.05 | BV27: 0.05 | BW27: 0.05 | BX27: 0.05 | BY27: 0.05 | BZ27: 0.05 | CA27: 0.05 | CB27: 0.05 | CC27: 0.05 | CD27: 0.05 | CE27: 0.05 | CF27: 0.05 | CG27: 0.05 | CH27: 0.05 | CI27: 0.05
A28: Transacciones Marketplace | B28: # | C28: ROUND(Premium_Activos*Market_Rate, 0) | D28: =ROUND(D21*D27, 0) -> 1 | E28: =ROUND(E21*E27, 0) -> 2 | F28: =ROUND(F21*F27, 0) -> 4 | G28: =ROUND(G21*G27, 0) -> 5 | H28: =ROUND(H21*H27, 0) -> 6 | I28: =ROUND(I21*I27, 0) -> 7 | J28: =ROUND(J21*J27, 0) -> 8 | K28: =ROUND(K21*K27, 0) -> 9 | ... CI28: =ROUND(CI21*CI27, 0) -> 496
A30: ESCENARIO 2: EQUILIBRIO (BREAK-EVEN) - 670 Hito
A31: Crecimiento Tráfico Orgánico | B31: % | C31: 0.08 | D31: 0.08 | E31: 0.08 | F31: 0.08 | G31: 0.08 | H31: 0.08 | I31: 0.08 | J31: 0.08 | K31: 0.08 | L31: 0.08 | M31: 0.08 | N31: 0.08 | O31: 0.08 | P31: 0.08 | Q31: 0.08 | R31: 0.08 | S31: 0.08 | T31: 0.08 | U31: 0.08 | V31: 0.08 | W31: 0.08 | X31: 0.08 | Y31: 0.08 | Z31: 0.08 | AA31: 0.08 | AB31: 0.08 | AC31: 0.08 | AD31: 0.08 | AE31: 0.08 | AF31: 0.08 | AG31: 0.08 | AH31: 0.08 | AI31: 0.08 | AJ31: 0.08 | AK31: 0.08 | AL31: 0.08 | AM31: 0.08 | AN31: 0.08 | AO31: 0.08 | AP31: 0.08 | AQ31: 0.08 | AR31: 0.08 | AS31: 0.08 | AT31: 0.08 | AU31: 0.08 | AV31: 0.08 | AW31: 0.08 | AX31: 0.08 | AY31: 0.08 | AZ31: 0.08 | BA31: 0.08 | BB31: 0.08 | BC31: 0.08 | BD31: 0.08 | BE31: 0.08 | BF31: 0.08 | BG31: 0.08 | BH31: 0.08 | BI31: 0.08 | BJ31: 0.08 | BK31: 0.08 | BL31: 0.08 | BM31: 0.08 | BN31: 0.08 | BO31: 0.08 | BP31: 0.08 | BQ31: 0.08 | BR31: 0.08 | BS31: 0.08 | BT31: 0.08 | BU31: 0.08 | BV31: 0.08 | BW31: 0.08 | BX31: 0.08 | BY31: 0.08 | BZ31: 0.08 | CA31: 0.08 | CB31: 0.08 | CC31: 0.08 | CD31: 0.08 | CE31: 0.08 | CF31: 0.08 | CG31: 0.08 | CH31: 0.08 | CI31: 0.08
A32: Tráfico Orgánico Mensual | B32: # | C32: M1=1000, Mt=Prev*(1+Growth) | D32: 2027 | E32: =D32*(1+E31) -> 2189.16 | F32: =E32*(1+F31) -> 2364.2928 | G32: =F32*(1+G31) -> 2553.4362 | H32: =G32*(1+H31) -> 2757.7111 | I32: =H32*(1+I31) -> 2978.328 | J32: =I32*(1+J31) -> 3216.5943 | K32: =J32*(1+K31) -> 3473.9218 | L32: =K32*(1+L31) -> 3751.8355 | ... CI32: =CH32*(1+CI31) -> 1205106.6
A33: Tasa de Conversión | B33: % | C33: 0.02 | D33: 0.02 | E33: 0.02 | F33: 0.02 | G33: 0.02 | H33: 0.02 | I33: 0.02 | J33: 0.02 | K33: 0.02 | L33: 0.02 | M33: 0.02 | N33: 0.02 | O33: 0.02 | P33: 0.02 | Q33: 0.02 | R33: 0.02 | S33: 0.02 | T33: 0.02 | U33: 0.02 | V33: 0.02 | W33: 0.02 | X33: 0.02 | Y33: 0.02 | Z33: 0.02 | AA33: 0.02 | AB33: 0.02 | AC33: 0.02 | AD33: 0.02 | AE33: 0.02 | AF33: 0.02 | AG33: 0.02 | AH33: 0.02 | AI33: 0.02 | AJ33: 0.02 | AK33: 0.02 | AL33: 0.02 | AM33: 0.02 | AN33: 0.02 | AO33: 0.02 | AP33: 0.02 | AQ33: 0.02 | AR33: 0.02 | AS33: 0.02 | AT33: 0.02 | AU33: 0.02 | AV33: 0.02 | AW33: 0.02 | AX33: 0.02 | AY33: 0.02 | AZ33: 0.02 | BA33: 0.02 | BB33: 0.02 | BC33: 0.02 | BD33: 0.02 | BE33: 0.02 | BF33: 0.02 | BG33: 0.02 | BH33: 0.02 | BI33: 0.02 | BJ33: 0.02 | BK33: 0.02 | BL33: 0.02 | BM33: 0.02 | BN33: 0.02 | BO33: 0.02 | BP33: 0.02 | BQ33: 0.02 | BR33: 0.02 | BS33: 0.02 | BT33: 0.02 | BU33: 0.02 | BV33: 0.02 | BW33: 0.02 | BX33: 0.02 | BY33: 0.02 | BZ33: 0.02 | CA33: 0.02 | CB33: 0.02 | CC33: 0.02 | CD33: 0.02 | CE33: 0.02 | CF33: 0.02 | CG33: 0.02 | CH33: 0.02 | CI33: 0.02
A34: Nuevos Clientes (Orgánicos) | B34: # | C34: ROUND(Tráfico*Conversión, 0) | D34: =ROUND(D32*D33, 0) -> 41 | E34: =ROUND(E32*E33, 0) -> 44 | F34: =ROUND(F32*F33, 0) -> 47 | G34: =ROUND(G32*G33, 0) -> 51 | H34: =ROUND(H32*H33, 0) -> 55 | I34: =ROUND(I32*I33, 0) -> 60 | J34: =ROUND(J32*J33, 0) -> 64 | K34: =ROUND(K32*K33, 0) -> 69 | ... CI34: =ROUND(CI32*CI33, 0) -> 24102
A35: Presupuesto Social Ads | B35: EUR | C35: '1_PANEL_CONTROL'!$C$80 | D35: ='1_PANEL_CONTROL'!$C$80+'1_PANEL_CONTROL'!$C$69+'1_PANEL_CONTROL'!$C$68 -> 2955 | E35: ='1_PANEL_CONTROL'!$C$80+'1_PANEL_CONTROL'!$C$69+'1_PANEL_CONTROL'!$C$68 -> 2955 | F35: ='1_PANEL_CONTROL'!$C$80+'1_PANEL_CONTROL'!$C$69+'1_PANEL_CONTROL'!$C$68 -> 2955 | G35: ='1_PANEL_CONTROL'!$C$80+'1_PANEL_CONTROL'!$C$69+'1_PANEL_CONTROL'!$C$68 -> 2955 | H35: ='1_PANEL_CONTROL'!$C$80+'1_PANEL_CONTROL'!$C$69+'1_PANEL_CONTROL'!$C$68 -> 2955 | I35: ='1_PANEL_CONTROL'!$C$80+'1_PANEL_CONTROL'!$C$69+'1_PANEL_CONTROL'!$C$68 -> 2955 | J35: ='1_PANEL_CONTROL'!$C$80+'1_PANEL_CONTROL'!$C$69+'1_PANEL_CONTROL'!$C$68 -> 2955 | K35: ='1_PANEL_CONTROL'!$C$80+'1_PANEL_CONTROL'!$C$69+'1_PANEL_CONTROL'!$C$68 -> 2955 | ... CI35: ='1_PANEL_CONTROL'!$C$80+'1_PANEL_CONTROL'!$C$69+'1_PANEL_CONTROL'!$C$68 -> 2955
A36: CPL Paid (Coste por Lead) | B36: EUR | C36: 11.0 | D36: 11 | E36: 11 | F36: 11 | G36: 11 | H36: 11 | I36: 11 | J36: 11 | K36: 11 | L36: 11 | M36: 11 | N36: 11 | O36: 11 | P36: 11 | Q36: 11 | R36: 11 | S36: 11 | T36: 11 | U36: 11 | V36: 11 | W36: 11 | X36: 11 | Y36: 11 | Z36: 11 | AA36: 11 | AB36: 11 | AC36: 11 | AD36: 11 | AE36: 11 | AF36: 11 | AG36: 11 | AH36: 11 | AI36: 11 | AJ36: 11 | AK36: 11 | AL36: 11 | AM36: 11 | AN36: 11 | AO36: 11 | AP36: 11 | AQ36: 11 | AR36: 11 | AS36: 11 | AT36: 11 | AU36: 11 | AV36: 11 | AW36: 11 | AX36: 11 | AY36: 11 | AZ36: 11 | BA36: 11 | BB36: 11 | BC36: 11 | BD36: 11 | BE36: 11 | BF36: 11 | BG36: 11 | BH36: 11 | BI36: 11 | BJ36: 11 | BK36: 11 | BL36: 11 | BM36: 11 | BN36: 11 | BO36: 11 | BP36: 11 | BQ36: 11 | BR36: 11 | BS36: 11 | BT36: 11 | BU36: 11 | BV36: 11 | BW36: 11 | BX36: 11 | BY36: 11 | BZ36: 11 | CA36: 11 | CB36: 11 | CC36: 11 | CD36: 11 | CE36: 11 | CF36: 11 | CG36: 11 | CH36: 11 | CI36: 11
A37: Leads de Pago Adquiridos | B37: # | C37: ROUND(Presupuesto/CPL, 0) | D37: =ROUND(D35/D36, 0) -> 269 | E37: =ROUND(E35/E36, 0) -> 269 | F37: =ROUND(F35/F36, 0) -> 269 | G37: =ROUND(G35/G36, 0) -> 269 | H37: =ROUND(H35/H36, 0) -> 269 | I37: =ROUND(I35/I36, 0) -> 269 | J37: =ROUND(J35/J36, 0) -> 269 | K37: =ROUND(K35/K36, 0) -> 269 | ... CI37: =ROUND(CI35/CI36, 0) -> 269
A38: Nuevos Clientes (Pauta/Paid) | B38: # | C38: ROUND(Leads*Conversión, 0) | D38: =ROUND(D37*D33, 0) -> 5 | E38: =ROUND(E37*E33, 0) -> 5 | F38: =ROUND(F37*F33, 0) -> 5 | G38: =ROUND(G37*G33, 0) -> 5 | H38: =ROUND(H37*H33, 0) -> 5 | I38: =ROUND(I37*I33, 0) -> 5 | J38: =ROUND(J37*J33, 0) -> 5 | K38: =ROUND(K37*K33, 0) -> 5 | ... CI38: =ROUND(CI37*CI33, 0) -> 5
A39: Nuevos Clientes Totales | B39: # | C39: Orgánicos + Paid | D39: =D34+D38 -> 46 | E39: =E34+E38 -> 49 | F39: =F34+F38 -> 52 | G39: =G34+G38 -> 56 | H39: =H34+H38 -> 60 | I39: =I34+I38 -> 65 | J39: =J34+J38 -> 69 | K39: =K34+K38 -> 74 | ... CI39: =CI34+CI38 -> 24107
A40: Tasa Cancelación (Churn) | B40: % | C40: 0.048 | D40: 0.048 | E40: 0.048 | F40: 0.048 | G40: 0.048 | H40: 0.048 | I40: 0.048 | J40: 0.048 | K40: 0.048 | L40: 0.048 | M40: 0.048 | N40: 0.048 | O40: 0.048 | P40: 0.048 | Q40: 0.048 | R40: 0.048 | S40: 0.048 | T40: 0.048 | U40: 0.048 | V40: 0.048 | W40: 0.048 | X40: 0.048 | Y40: 0.048 | Z40: 0.048 | AA40: 0.048 | AB40: 0.048 | AC40: 0.048 | AD40: 0.048 | AE40: 0.048 | AF40: 0.048 | AG40: 0.048 | AH40: 0.048 | AI40: 0.048 | AJ40: 0.048 | AK40: 0.048 | AL40: 0.048 | AM40: 0.048 | AN40: 0.048 | AO40: 0.048 | AP40: 0.048 | AQ40: 0.048 | AR40: 0.048 | AS40: 0.048 | AT40: 0.048 | AU40: 0.048 | AV40: 0.048 | AW40: 0.048 | AX40: 0.048 | AY40: 0.048 | AZ40: 0.048 | BA40: 0.048 | BB40: 0.048 | BC40: 0.048 | BD40: 0.048 | BE40: 0.048 | BF40: 0.048 | BG40: 0.048 | BH40: 0.048 | BI40: 0.048 | BJ40: 0.048 | BK40: 0.048 | BL40: 0.048 | BM40: 0.048 | BN40: 0.048 | BO40: 0.048 | BP40: 0.048 | BQ40: 0.048 | BR40: 0.048 | BS40: 0.048 | BT40: 0.048 | BU40: 0.048 | BV40: 0.048 | BW40: 0.048 | BX40: 0.048 | BY40: 0.048 | BZ40: 0.048 | CA40: 0.048 | CB40: 0.048 | CC40: 0.048 | CD40: 0.048 | CE40: 0.048 | CF40: 0.048 | CG40: 0.048 | CH40: 0.048 | CI40: 0.048
A41: Clientes Activos (Premium Care) | B41: # | C41: M1=Nuevos, Mt=ROUND(Prev*(1-Churn)+Nuevos, 0) | D41: =D39 -> 46 | E41: =ROUND(D41*(1-E40)+E39, 0) -> 93 | F41: =ROUND(E41*(1-F40)+F39, 0) -> 141 | G41: =ROUND(F41*(1-G40)+G39, 0) -> 190 | H41: =ROUND(G41*(1-H40)+H39, 0) -> 241 | I41: =ROUND(H41*(1-I40)+I39, 0) -> 294 | J41: =ROUND(I41*(1-J40)+J39, 0) -> 349 | K41: =ROUND(J41*(1-K40)+K39, 0) -> 406 | L41: =ROUND(K41*(1-L40)+L39, 0) -> 467 | ... CI41: =ROUND(CH41*(1-CI40)+CI39, 0) -> 203460
A42: Attachment CUDI Shield Basic | B42: % | C42: 0.3 | D42: 0.3 | E42: 0.3 | F42: 0.3 | G42: 0.3 | H42: 0.3 | I42: 0.3 | J42: 0.3 | K42: 0.3 | L42: 0.3 | M42: 0.3 | N42: 0.3 | O42: 0.3 | P42: 0.3 | Q42: 0.3 | R42: 0.3 | S42: 0.3 | T42: 0.3 | U42: 0.3 | V42: 0.3 | W42: 0.3 | X42: 0.3 | Y42: 0.3 | Z42: 0.3 | AA42: 0.3 | AB42: 0.3 | AC42: 0.3 | AD42: 0.3 | AE42: 0.3 | AF42: 0.3 | AG42: 0.3 | AH42: 0.3 | AI42: 0.3 | AJ42: 0.3 | AK42: 0.3 | AL42: 0.3 | AM42: 0.3 | AN42: 0.3 | AO42: 0.3 | AP42: 0.3 | AQ42: 0.3 | AR42: 0.3 | AS42: 0.3 | AT42: 0.3 | AU42: 0.3 | AV42: 0.3 | AW42: 0.3 | AX42: 0.3 | AY42: 0.3 | AZ42: 0.3 | BA42: 0.3 | BB42: 0.3 | BC42: 0.3 | BD42: 0.3 | BE42: 0.3 | BF42: 0.3 | BG42: 0.3 | BH42: 0.3 | BI42: 0.3 | BJ42: 0.3 | BK42: 0.3 | BL42: 0.3 | BM42: 0.3 | BN42: 0.3 | BO42: 0.3 | BP42: 0.3 | BQ42: 0.3 | BR42: 0.3 | BS42: 0.3 | BT42: 0.3 | BU42: 0.3 | BV42: 0.3 | BW42: 0.3 | BX42: 0.3 | BY42: 0.3 | BZ42: 0.3 | CA42: 0.3 | CB42: 0.3 | CC42: 0.3 | CD42: 0.3 | CE42: 0.3 | CF42: 0.3 | CG42: 0.3 | CH42: 0.3 | CI42: 0.3
A43: Clientes Activos Shield Seguro | B43: # | C43: ROUND(Premium_Activos*Attachment, 0) | D43: =ROUND(D41*D42, 0) -> 14 | E43: =ROUND(E41*E42, 0) -> 28 | F43: =ROUND(F41*F42, 0) -> 42 | G43: =ROUND(G41*G42, 0) -> 57 | H43: =ROUND(H41*H42, 0) -> 72 | I43: =ROUND(I41*I42, 0) -> 88 | J43: =ROUND(J41*J42, 0) -> 105 | K43: =ROUND(K41*K42, 0) -> 122 | ... CI43: =ROUND(CI41*CI42, 0) -> 61038
A44: Smart Collars Vendidos | B44: # | C44: Nuevos Clientes Totales | D44: =D39 -> 46 | E44: =E39 -> 49 | F44: =F39 -> 52 | G44: =G39 -> 56 | H44: =H39 -> 60 | I44: =I39 -> 65 | J44: =J39 -> 69 | K44: =K39 -> 74 | ... CI44: =CI39 -> 24107
A45: Tasa Visitas VetHome | B45: % | C45: 0.045 | D45: 0.045 | E45: 0.045 | F45: 0.045 | G45: 0.045 | H45: 0.045 | I45: 0.045 | J45: 0.045 | K45: 0.045 | L45: 0.045 | M45: 0.045 | N45: 0.045 | O45: 0.045 | P45: 0.045 | Q45: 0.045 | R45: 0.045 | S45: 0.045 | T45: 0.045 | U45: 0.045 | V45: 0.045 | W45: 0.045 | X45: 0.045 | Y45: 0.045 | Z45: 0.045 | AA45: 0.045 | AB45: 0.045 | AC45: 0.045 | AD45: 0.045 | AE45: 0.045 | AF45: 0.045 | AG45: 0.045 | AH45: 0.045 | AI45: 0.045 | AJ45: 0.045 | AK45: 0.045 | AL45: 0.045 | AM45: 0.045 | AN45: 0.045 | AO45: 0.045 | AP45: 0.045 | AQ45: 0.045 | AR45: 0.045 | AS45: 0.045 | AT45: 0.045 | AU45: 0.045 | AV45: 0.045 | AW45: 0.045 | AX45: 0.045 | AY45: 0.045 | AZ45: 0.045 | BA45: 0.045 | BB45: 0.045 | BC45: 0.045 | BD45: 0.045 | BE45: 0.045 | BF45: 0.045 | BG45: 0.045 | BH45: 0.045 | BI45: 0.045 | BJ45: 0.045 | BK45: 0.045 | BL45: 0.045 | BM45: 0.045 | BN45: 0.045 | BO45: 0.045 | BP45: 0.045 | BQ45: 0.045 | BR45: 0.045 | BS45: 0.045 | BT45: 0.045 | BU45: 0.045 | BV45: 0.045 | BW45: 0.045 | BX45: 0.045 | BY45: 0.045 | BZ45: 0.045 | CA45: 0.045 | CB45: 0.045 | CC45: 0.045 | CD45: 0.045 | CE45: 0.045 | CF45: 0.045 | CG45: 0.045 | CH45: 0.045 | CI45: 0.045
A46: Visitas VetHome Proyectadas | B46: # | C46: ROUND(Premium_Activos*VetHome_Rate, 0) | D46: =ROUND(D41*D45, 0) -> 2 | E46: =ROUND(E41*E45, 0) -> 4 | F46: =ROUND(F41*F45, 0) -> 6 | G46: =ROUND(G41*G45, 0) -> 9 | H46: =ROUND(H41*H45, 0) -> 11 | I46: =ROUND(I41*I45, 0) -> 13 | J46: =ROUND(J41*J45, 0) -> 16 | K46: =ROUND(K41*K45, 0) -> 18 | ... CI46: =ROUND(CI41*CI45, 0) -> 9156
A47: Tasa Compras Marketplace | B47: % | C47: 0.2 | D47: 0.2 | E47: 0.2 | F47: 0.2 | G47: 0.2 | H47: 0.2 | I47: 0.2 | J47: 0.2 | K47: 0.2 | L47: 0.2 | M47: 0.2 | N47: 0.2 | O47: 0.2 | P47: 0.2 | Q47: 0.2 | R47: 0.2 | S47: 0.2 | T47: 0.2 | U47: 0.2 | V47: 0.2 | W47: 0.2 | X47: 0.2 | Y47: 0.2 | Z47: 0.2 | AA47: 0.2 | AB47: 0.2 | AC47: 0.2 | AD47: 0.2 | AE47: 0.2 | AF47: 0.2 | AG47: 0.2 | AH47: 0.2 | AI47: 0.2 | AJ47: 0.2 | AK47: 0.2 | AL47: 0.2 | AM47: 0.2 | AN47: 0.2 | AO47: 0.2 | AP47: 0.2 | AQ47: 0.2 | AR47: 0.2 | AS47: 0.2 | AT47: 0.2 | AU47: 0.2 | AV47: 0.2 | AW47: 0.2 | AX47: 0.2 | AY47: 0.2 | AZ47: 0.2 | BA47: 0.2 | BB47: 0.2 | BC47: 0.2 | BD47: 0.2 | BE47: 0.2 | BF47: 0.2 | BG47: 0.2 | BH47: 0.2 | BI47: 0.2 | BJ47: 0.2 | BK47: 0.2 | BL47: 0.2 | BM47: 0.2 | BN47: 0.2 | BO47: 0.2 | BP47: 0.2 | BQ47: 0.2 | BR47: 0.2 | BS47: 0.2 | BT47: 0.2 | BU47: 0.2 | BV47: 0.2 | BW47: 0.2 | BX47: 0.2 | BY47: 0.2 | BZ47: 0.2 | CA47: 0.2 | CB47: 0.2 | CC47: 0.2 | CD47: 0.2 | CE47: 0.2 | CF47: 0.2 | CG47: 0.2 | CH47: 0.2 | CI47: 0.2
...

Sheet 5_DETALLE_INGRESOS
A4: MODELO DE INGRESOS MENSUAL DE CUDI
A5: Escenario Activo: | B5: =CHOOSE('1_PANEL_CONTROL'!$C$4, "🔴 1: NEGATIVO", "🟡 2: EQUILIBRIO", "🟢 3: POSITIVO") -> 🟡 2: EQUILIBRIO | D5: =CHOOSE('1_PANEL_CONTROL'!$C$4, "[NEGATIVO] PLAN DE INGRESOS MENSUALES. La facturación Premium Care en mes 12 es de " & TEXT('5_DETALLE_INGRESOS'!O26, "#.##0 €") & ", acumulando una facturación consolidada en el primer año de " & TEXT(SUM('5_DETALLE_INGRESOS'!$D$37:$O$37), "#.##0 €") & ".", "[EQUILIBRIO] PLAN DE INGRESOS MENSUALES. En el mes 12, el seguro Shield aporta " & TEXT('5_DETALLE_INGRESOS'!O27, "#.##0 €") & " y el B2B/Afiliados genera " & TEXT('5_DETALLE_INGRESOS'!O36, "#.##0 €") & " adicionales sobre base Premium Care.", "[POSITIVO] PLAN DE INGRESOS MENSUALES. En el mes 12, los ingresos B2B y seguros aportan " & TEXT('5_DETALLE_INGRESOS'!O36, "#.##0 €") & ", elevando la facturación total a " & TEXT(SUM('5_DETALLE_INGRESOS'!$D$37:$O$37), "#.##0 €") & " en Año 1.") -> [EQUILIBRIO] PLAN DE INGRESOS MENSUALES. En el mes 12, el seguro Shield aporta 1.868 € y el B2B/Afiliados genera 8.209 € adicionales sobre base Premium Care.
A7: Métricas de Volumen | B7: Unidad | C7: Fórmula / Regla | D7: Ene-26 | E7: Feb-26 | F7: Mar-26 | G7: Abr-26 | H7: May-26 | I7: Jun-26 | J7: Jul-26 | K7: Ago-26 | L7: Sep-26 | M7: Oct-26 | N7: Nov-26 | O7: Dic-26 | P7: Ene-27 | Q7: Feb-27 | R7: Mar-27 | S7: Abr-27 | T7: May-27 | U7: Jun-27 | V7: Jul-27 | W7: Ago-27 | X7: Sep-27 | Y7: Oct-27 | Z7: Nov-27 | AA7: Dic-27 | AB7: Ene-28 | AC7: Feb-28 | AD7: Mar-28 | AE7: Abr-28 | AF7: May-28 | AG7: Jun-28 | AH7: Jul-28 | AI7: Ago-28 | AJ7: Sep-28 | AK7: Oct-28 | AL7: Nov-28 | AM7: Dic-28 | AN7: Ene-29 | AO7: Feb-29 | AP7: Mar-29 | AQ7: Abr-29 | AR7: May-29 | AS7: Jun-29 | AT7: Jul-29 | AU7: Ago-29 | AV7: Sep-29 | AW7: Oct-29 | AX7: Nov-29 | AY7: Dic-29 | AZ7: Ene-30 | BA7: Feb-30 | BB7: Mar-30 | BC7: Abr-30 | BD7: May-30 | BE7: Jun-30 | BF7: Jul-30 | BG7: Ago-30 | BH7: Sep-30 | BI7: Oct-30 | BJ7: Nov-30 | BK7: Dic-30 | BL7: Ene-31 | BM7: Feb-31 | BN7: Mar-31 | BO7: Abr-31 | BP7: May-31 | BQ7: Jun-31 | BR7: Jul-31 | BS7: Ago-31 | BT7: Sep-31 | BU7: Oct-31 | BV7: Nov-31 | BW7: Dic-31 | BX7: Ene-32 | BY7: Feb-32 | BZ7: Mar-32 | CA7: Abr-32 | CB7: May-32 | CC7: Jun-32 | CD7: Jul-32 | CE7: Ago-32 | CF7: Sep-32 | CG7: Oct-32 | CH7: Nov-32 | CI7: Dic-32
A10: Tráfico Orgánico | B10: # | C10: Link a '4_PROY_DEMANDA'!Row 71 | D10: ='4_PROY_DEMANDA'!D72 -> 2027 | E10: ='4_PROY_DEMANDA'!E72 -> 2189.16 | F10: ='4_PROY_DEMANDA'!F72 -> 2364.2928 | G10: ='4_PROY_DEMANDA'!G72 -> 2553.4362 | H10: ='4_PROY_DEMANDA'!H72 -> 2757.7111 | I10: ='4_PROY_DEMANDA'!I72 -> 2978.328 | J10: ='4_PROY_DEMANDA'!J72 -> 3216.5943 | K10: ='4_PROY_DEMANDA'!K72 -> 3473.9218 | ... CI10: ='4_PROY_DEMANDA'!CI72 -> 1205106.6
A11: Tasa de Conversión | B11: % | C11: Link a '4_PROY_DEMANDA'!Row 72 | D11: ='4_PROY_DEMANDA'!D73 -> 0.02 | E11: ='4_PROY_DEMANDA'!E73 -> 0.02 | F11: ='4_PROY_DEMANDA'!F73 -> 0.02 | G11: ='4_PROY_DEMANDA'!G73 -> 0.02 | H11: ='4_PROY_DEMANDA'!H73 -> 0.02 | I11: ='4_PROY_DEMANDA'!I73 -> 0.02 | J11: ='4_PROY_DEMANDA'!J73 -> 0.02 | K11: ='4_PROY_DEMANDA'!K73 -> 0.02 | ... CI11: ='4_PROY_DEMANDA'!CI73 -> 0.02
A12: Nuevos Clientes (Orgánicos) | B12: # | C12: Link a '4_PROY_DEMANDA'!Row 73 | D12: ='4_PROY_DEMANDA'!D74 -> 41 | E12: ='4_PROY_DEMANDA'!E74 -> 44 | F12: ='4_PROY_DEMANDA'!F74 -> 47 | G12: ='4_PROY_DEMANDA'!G74 -> 51 | H12: ='4_PROY_DEMANDA'!H74 -> 55 | I12: ='4_PROY_DEMANDA'!I74 -> 60 | J12: ='4_PROY_DEMANDA'!J74 -> 64 | K12: ='4_PROY_DEMANDA'!K74 -> 69 | ... CI12: ='4_PROY_DEMANDA'!CI74 -> 24102
A13: Presupuesto Publicitario | B13: EUR | C13: Link a '4_PROY_DEMANDA'!Row 74 | D13: ='4_PROY_DEMANDA'!D75 -> 2955 | E13: ='4_PROY_DEMANDA'!E75 -> 2955 | F13: ='4_PROY_DEMANDA'!F75 -> 2955 | G13: ='4_PROY_DEMANDA'!G75 -> 2955 | H13: ='4_PROY_DEMANDA'!H75 -> 2955 | I13: ='4_PROY_DEMANDA'!I75 -> 2955 | J13: ='4_PROY_DEMANDA'!J75 -> 2955 | K13: ='4_PROY_DEMANDA'!K75 -> 2955 | ... CI13: ='4_PROY_DEMANDA'!CI75 -> 2955
A14: CAC Paid (CPL de Pago) | B14: EUR | C14: Link a '4_PROY_DEMANDA'!Row 75 | D14: ='4_PROY_DEMANDA'!D76 -> 11 | E14: ='4_PROY_DEMANDA'!E76 -> 11 | F14: ='4_PROY_DEMANDA'!F76 -> 11 | G14: ='4_PROY_DEMANDA'!G76 -> 11 | H14: ='4_PROY_DEMANDA'!H76 -> 11 | I14: ='4_PROY_DEMANDA'!I76 -> 11 | J14: ='4_PROY_DEMANDA'!J76 -> 11 | K14: ='4_PROY_DEMANDA'!K76 -> 11 | ... CI14: ='4_PROY_DEMANDA'!CI76 -> 11
A15: Nuevos Clientes (Pauta/Paid) | B15: # | C15: Link a '4_PROY_DEMANDA'!Row 77 | D15: ='4_PROY_DEMANDA'!D78 -> 5 | E15: ='4_PROY_DEMANDA'!E78 -> 5 | F15: ='4_PROY_DEMANDA'!F78 -> 5 | G15: ='4_PROY_DEMANDA'!G78 -> 5 | H15: ='4_PROY_DEMANDA'!H78 -> 5 | I15: ='4_PROY_DEMANDA'!I78 -> 5 | J15: ='4_PROY_DEMANDA'!J78 -> 5 | K15: ='4_PROY_DEMANDA'!K78 -> 5 | ... CI15: ='4_PROY_DEMANDA'!CI78 -> 5
A16: Nuevos Clientes Totales | B16: # | C16: Link a '4_PROY_DEMANDA'!Row 78 | D16: ='4_PROY_DEMANDA'!D79 -> 46 | E16: ='4_PROY_DEMANDA'!E79 -> 49 | F16: ='4_PROY_DEMANDA'!F79 -> 52 | G16: ='4_PROY_DEMANDA'!G79 -> 56 | H16: ='4_PROY_DEMANDA'!H79 -> 60 | I16: ='4_PROY_DEMANDA'!I79 -> 65 | J16: ='4_PROY_DEMANDA'!J79 -> 69 | K16: ='4_PROY_DEMANDA'!K79 -> 74 | ... CI16: ='4_PROY_DEMANDA'!CI79 -> 24107
A17: Tasa de Cancelación (Churn) | B17: % | C17: Link a '4_PROY_DEMANDA'!Row 79 | D17: ='4_PROY_DEMANDA'!D80 -> 0.048 | E17: ='4_PROY_DEMANDA'!E80 -> 0.048 | F17: ='4_PROY_DEMANDA'!F80 -> 0.048 | G17: ='4_PROY_DEMANDA'!G80 -> 0.048 | H17: ='4_PROY_DEMANDA'!H80 -> 0.048 | I17: ='4_PROY_DEMANDA'!I80 -> 0.048 | J17: ='4_PROY_DEMANDA'!J80 -> 0.048 | K17: ='4_PROY_DEMANDA'!K80 -> 0.048 | ... CI17: ='4_PROY_DEMANDA'!CI80 -> 0.048
A18: Clientes Activos (Premium Care) | B18: # | C18: Link a '4_PROY_DEMANDA'!Row 80 | D18: ='4_PROY_DEMANDA'!D81 -> 46 | E18: ='4_PROY_DEMANDA'!E81 -> 93 | F18: ='4_PROY_DEMANDA'!F81 -> 141 | G18: ='4_PROY_DEMANDA'!G81 -> 190 | H18: ='4_PROY_DEMANDA'!H81 -> 241 | I18: ='4_PROY_DEMANDA'!I81 -> 294 | J18: ='4_PROY_DEMANDA'!J81 -> 349 | K18: ='4_PROY_DEMANDA'!K81 -> 406 | ... CI18: ='4_PROY_DEMANDA'!CI81 -> 203460
A19: Clientes Activos (Shield Seguro) | B19: # | C19: Link a '4_PROY_DEMANDA'!Row 82 | D19: ='4_PROY_DEMANDA'!D83 -> 14 | E19: ='4_PROY_DEMANDA'!E83 -> 28 | F19: ='4_PROY_DEMANDA'!F83 -> 42 | G19: ='4_PROY_DEMANDA'!G83 -> 57 | H19: ='4_PROY_DEMANDA'!H83 -> 72 | I19: ='4_PROY_DEMANDA'!I83 -> 88 | J19: ='4_PROY_DEMANDA'!J83 -> 105 | K19: ='4_PROY_DEMANDA'!K83 -> 122 | ... CI19: ='4_PROY_DEMANDA'!CI83 -> 61038
A20: Smart Collars Vendidos | B20: # | C20: Link a '4_PROY_DEMANDA'!Row 83 | D20: ='4_PROY_DEMANDA'!D84 -> 46 | E20: ='4_PROY_DEMANDA'!E84 -> 49 | F20: ='4_PROY_DEMANDA'!F84 -> 52 | G20: ='4_PROY_DEMANDA'!G84 -> 56 | H20: ='4_PROY_DEMANDA'!H84 -> 60 | I20: ='4_PROY_DEMANDA'!I84 -> 65 | J20: ='4_PROY_DEMANDA'!J84 -> 69 | K20: ='4_PROY_DEMANDA'!K84 -> 74 | ... CI20: ='4_PROY_DEMANDA'!CI84 -> 24107
A21: Visitas VetHome | B21: # | C21: Link a '4_PROY_DEMANDA'!Row 85 | D21: ='4_PROY_DEMANDA'!D86 -> 2 | E21: ='4_PROY_DEMANDA'!E86 -> 4 | F21: ='4_PROY_DEMANDA'!F86 -> 6 | G21: ='4_PROY_DEMANDA'!G86 -> 9 | H21: ='4_PROY_DEMANDA'!H86 -> 11 | I21: ='4_PROY_DEMANDA'!I86 -> 13 | J21: ='4_PROY_DEMANDA'!J86 -> 16 | K21: ='4_PROY_DEMANDA'!K86 -> 18 | ... CI21: ='4_PROY_DEMANDA'!CI86 -> 9156
A22: Compradores Marketplace | B22: # | C22: Link a '4_PROY_DEMANDA'!Row 87 | D22: ='4_PROY_DEMANDA'!D88 -> 9 | E22: ='4_PROY_DEMANDA'!E88 -> 19 | F22: ='4_PROY_DEMANDA'!F88 -> 28 | G22: ='4_PROY_DEMANDA'!G88 -> 38 | H22: ='4_PROY_DEMANDA'!H88 -> 48 | I22: ='4_PROY_DEMANDA'!I88 -> 59 | J22: ='4_PROY_DEMANDA'!J88 -> 70 | K22: ='4_PROY_DEMANDA'!K88 -> 81 | ... CI22: ='4_PROY_DEMANDA'!CI88 -> 40692
A24: DESGLOSE DE INGRESOS (EUR)
A26: Suscripción Premium Care (SaaS) | B26: EUR | C26: ActivePremium * PriceSuscrip | D26: =D18*(1-'1_PANEL_CONTROL'!$C$138)*'1_PANEL_CONTROL'!$C$15 + D18*'1_PANEL_CONTROL'!$C$138*'1_PANEL_CONTROL'!$C$15*(1-'1_PANEL_CONTROL'!$C$139) -> 1317.9 | E26: =E18*(1-'1_PANEL_CONTROL'!$C$138)*'1_PANEL_CONTROL'!$C$15 + E18*'1_PANEL_CONTROL'!$C$138*'1_PANEL_CONTROL'!$C$15*(1-'1_PANEL_CONTROL'!$C$139) -> 2664.45 | F26: =F18*(1-'1_PANEL_CONTROL'!$C$138)*'1_PANEL_CONTROL'!$C$15 + F18*'1_PANEL_CONTROL'!$C$138*'1_PANEL_CONTROL'!$C$15*(1-'1_PANEL_CONTROL'!$C$139) -> 4039.65 | G26: =G18*(1-'1_PANEL_CONTROL'!$C$138)*'1_PANEL_CONTROL'!$C$15 + G18*'1_PANEL_CONTROL'!$C$138*'1_PANEL_CONTROL'!$C$15*(1-'1_PANEL_CONTROL'!$C$139) -> 5443.5 | H26: =H18*(1-'1_PANEL_CONTROL'!$C$138)*'1_PANEL_CONTROL'!$C$15 + H18*'1_PANEL_CONTROL'!$C$138*'1_PANEL_CONTROL'!$C$15*(1-'1_PANEL_CONTROL'!$C$139) -> 6904.65 | I26: =I18*(1-'1_PANEL_CONTROL'!$C$138)*'1_PANEL_CONTROL'!$C$15 + I18*'1_PANEL_CONTROL'!$C$138*'1_PANEL_CONTROL'!$C$15*(1-'1_PANEL_CONTROL'!$C$139) -> 8423.1 | J26: =J18*(1-'1_PANEL_CONTROL'!$C$138)*'1_PANEL_CONTROL'!$C$15 + J18*'1_PANEL_CONTROL'!$C$138*'1_PANEL_CONTROL'!$C$15*(1-'1_PANEL_CONTROL'!$C$139) -> 9998.85 | K26: =K18*(1-'1_PANEL_CONTROL'!$C$138)*'1_PANEL_CONTROL'!$C$15 + K18*'1_PANEL_CONTROL'!$C$138*'1_PANEL_CONTROL'!$C$15*(1-'1_PANEL_CONTROL'!$C$139) -> 11631.9 | ... CI26: =CI18*(1-'1_PANEL_CONTROL'!$C$138)*'1_PANEL_CONTROL'!$C$15 + CI18*'1_PANEL_CONTROL'!$C$138*'1_PANEL_CONTROL'!$C$15*(1-'1_PANEL_CONTROL'!$C$139) -> 5829129
A27: Seguro CUDI Shield Basic | B27: EUR | C27: ActiveShield * PriceShield | D27: =D19*'1_PANEL_CONTROL'!$C$128+D16*CHOOSE('1_PANEL_CONTROL'!$C$4, '1_PANEL_CONTROL'!$C$118, '1_PANEL_CONTROL'!$C$119, '1_PANEL_CONTROL'!$C$120)*CHOOSE('1_PANEL_CONTROL'!$C$4, '1_PANEL_CONTROL'!$C$121, '1_PANEL_CONTROL'!$C$122, '1_PANEL_CONTROL'!$C$123)+D16*CHOOSE('1_PANEL_CONTROL'!$C$4, '1_PANEL_CONTROL'!$C$118, '1_PANEL_CONTROL'!$C$119, '1_PANEL_CONTROL'!$C$120)*CHOOSE('1_PANEL_CONTROL'!$C$4, '1_PANEL_CONTROL'!$C$124, '1_PANEL_CONTROL'!$C$125, '1_PANEL_CONTROL'!$C$126)*'1_PANEL_CONTROL'!$C$127 -> 466.75 | E27: =E19*'1_PANEL_CONTROL'!$C$128+E16*CHOOSE('1_PANEL_CONTROL'!$C$4, '1_PANEL_CONTROL'!$C$118, '1_PANEL_CONTROL'!$C$119, '1_PANEL_CONTROL'!$C$120)*CHOOSE('1_PANEL_CONTROL'!$C$4, '1_PANEL_CONTROL'!$C$121, '1_PANEL_CONTROL'!$C$122, '1_PANEL_CONTROL'!$C$123)+E16*CHOOSE('1_PANEL_CONTROL'!$C$4, '1_PANEL_CONTROL'!$C$118, '1_PANEL_CONTROL'!$C$119, '1_PANEL_CONTROL'!$C$120)*CHOOSE('1_PANEL_CONTROL'!$C$4, '1_PANEL_CONTROL'!$C$124, '1_PANEL_CONTROL'!$C$125, '1_PANEL_CONTROL'!$C$126)*'1_PANEL_CONTROL'!$C$127 -> 562.625 | F27: =F19*'1_PANEL_CONTROL'!$C$128+F16*CHOOSE('1_PANEL_CONTROL'!$C$4, '1_PANEL_CONTROL'!$C$118, '1_PANEL_CONTROL'!$C$119, '1_PANEL_CONTROL'!$C$120)*CHOOSE('1_PANEL_CONTROL'!$C$4, '1_PANEL_CONTROL'!$C$121, '1_PANEL_CONTROL'!$C$122, '1_PANEL_CONTROL'!$C$123)+F16*CHOOSE('1_PANEL_CONTROL'!$C$4, '1_PANEL_CONTROL'!$C$118, '1_PANEL_CONTROL'!$C$119, '1_PANEL_CONTROL'!$C$120)*CHOOSE('1_PANEL_CONTROL'!$C$4, '1_PANEL_CONTROL'!$C$124, '1_PANEL_CONTROL'!$C$125, '1_PANEL_CONTROL'!$C$126)*'1_PANEL_CONTROL'!$C$127 -> 658.5 | G27: =G19*'1_PANEL_CONTROL'!$C$128+G16*CHOOSE('1_PANEL_CONTROL'!$C$4, '1_PANEL_CONTROL'!$C$118, '1_PANEL_CONTROL'!$C$119, '1_PANEL_CONTROL'!$C$120)*CHOOSE('1_PANEL_CONTROL'!$C$4, '1_PANEL_CONTROL'!$C$121, '1_PANEL_CONTROL'!$C$122, '1_PANEL_CONTROL'!$C$123)+G16*CHOOSE('1_PANEL_CONTROL'!$C$4, '1_PANEL_CONTROL'!$C$118, '1_PANEL_CONTROL'!$C$119, '1_PANEL_CONTROL'!$C$120)*CHOOSE('1_PANEL_CONTROL'!$C$4, '1_PANEL_CONTROL'!$C$124, '1_PANEL_CONTROL'!$C$125, '1_PANEL_CONTROL'!$C$126)*'1_PANEL_CONTROL'!$C$127 -> 768 | H27: =H19*'1_PANEL_CONTROL'!$C$128+H16*CHOOSE('1_PANEL_CONTROL'!$C$4, '1_PANEL_CONTROL'!$C$118, '1_PANEL_CONTROL'!$C$119, '1_PANEL_CONTROL'!$C$120)*CHOOSE('1_PANEL_CONTROL'!$C$4, '1_PANEL_CONTROL'!$C$121, '1_PANEL_CONTROL'!$C$122, '1_PANEL_CONTROL'!$C$123)+H16*CHOOSE('1_PANEL_CONTROL'!$C$4, '1_PANEL_CONTROL'!$C$118, '1_PANEL_CONTROL'!$C$119, '1_PANEL_CONTROL'!$C$120)*CHOOSE('1_PANEL_CONTROL'!$C$4, '1_PANEL_CONTROL'!$C$124, '1_PANEL_CONTROL'!$C$125, '1_PANEL_CONTROL'!$C$126)*'1_PANEL_CONTROL'!$C$127 -> 877.5 | I27: =I19*'1_PANEL_CONTROL'!$C$128+I16*CHOOSE('1_PANEL_CONTROL'!$C$4, '1_PANEL_CONTROL'!$C$118, '1_PANEL_CONTROL'!$C$119, '1_PANEL_CONTROL'!$C$120)*CHOOSE('1_PANEL_CONTROL'!$C$4, '1_PANEL_CONTROL'!$C$121, '1_PANEL_CONTROL'!$C$122, '1_PANEL_CONTROL'!$C$123)+I16*CHOOSE('1_PANEL_CONTROL'!$C$4, '1_PANEL_CONTROL'!$C$118, '1_PANEL_CONTROL'!$C$119, '1_PANEL_CONTROL'!$C$120)*CHOOSE('1_PANEL_CONTROL'!$C$4, '1_PANEL_CONTROL'!$C$124, '1_PANEL_CONTROL'!$C$125, '1_PANEL_CONTROL'!$C$126)*'1_PANEL_CONTROL'!$C$127 -> 1000.625 | J27: =J19*'1_PANEL_CONTROL'!$C$128+J16*CHOOSE('1_PANEL_CONTROL'!$C$4, '1_PANEL_CONTROL'!$C$118, '1_PANEL_CONTROL'!$C$119, '1_PANEL_CONTROL'!$C$120)*CHOOSE('1_PANEL_CONTROL'!$C$4, '1_PANEL_CONTROL'!$C$121, '1_PANEL_CONTROL'!$C$122, '1_PANEL_CONTROL'!$C$123)+J16*CHOOSE('1_PANEL_CONTROL'!$C$4, '1_PANEL_CONTROL'!$C$118, '1_PANEL_CONTROL'!$C$119, '1_PANEL_CONTROL'!$C$120)*CHOOSE('1_PANEL_CONTROL'!$C$4, '1_PANEL_CONTROL'!$C$124, '1_PANEL_CONTROL'!$C$125, '1_PANEL_CONTROL'!$C$126)*'1_PANEL_CONTROL'!$C$127 -> 1120.125 | K27: =K19*'1_PANEL_CONTROL'!$C$128+K16*CHOOSE('1_PANEL_CONTROL'!$C$4, '1_PANEL_CONTROL'!$C$118, '1_PANEL_CONTROL'!$C$119, '1_PANEL_CONTROL'!$C$120)*CHOOSE('1_PANEL_CONTROL'!$C$4, '1_PANEL_CONTROL'!$C$121, '1_PANEL_CONTROL'!$C$122, '1_PANEL_CONTROL'!$C$123)+K16*CHOOSE('1_PANEL_CONTROL'!$C$4, '1_PANEL_CONTROL'!$C$118, '1_PANEL_CONTROL'!$C$119, '1_PANEL_CONTROL'!$C$120)*CHOOSE('1_PANEL_CONTROL'!$C$4, '1_PANEL_CONTROL'!$C$124, '1_PANEL_CONTROL'!$C$125, '1_PANEL_CONTROL'!$C$126)*'1_PANEL_CONTROL'!$C$127 -> 1248.25 | ... CI27: =CI19*'1_PANEL_CONTROL'!$C$128+CI16*CHOOSE('1_PANEL_CONTROL'!$C$4, '1_PANEL_CONTROL'!$C$118, '1_PANEL_CONTROL'!$C$119, '1_PANEL_CONTROL'!$C$120)*CHOOSE('1_PANEL_CONTROL'!$C$4, '1_PANEL_CONTROL'!$C$121, '1_PANEL_CONTROL'!$C$122, '1_PANEL_CONTROL'!$C$123)+CI16*CHOOSE('1_PANEL_CONTROL'!$C$4, '1_PANEL_CONTROL'!$C$118, '1_PANEL_CONTROL'!$C$119, '1_PANEL_CONTROL'!$C$120)*CHOOSE('1_PANEL_CONTROL'!$C$4, '1_PANEL_CONTROL'!$C$124, '1_PANEL_CONTROL'!$C$125, '1_PANEL_CONTROL'!$C$126)*'1_PANEL_CONTROL'!$C$127 -> 513112.88
A28: Venta Collares (Hardware) | B28: EUR | C28: CollarsSold * PriceCollar | D28: =D20*'1_PANEL_CONTROL'!$C$16 -> 4117 | E28: =E20*'1_PANEL_CONTROL'!$C$16 -> 4385.5 | F28: =F20*'1_PANEL_CONTROL'!$C$16 -> 4654 | G28: =G20*'1_PANEL_CONTROL'!$C$16 -> 5012 | H28: =H20*'1_PANEL_CONTROL'!$C$16 -> 5370 | I28: =I20*'1_PANEL_CONTROL'!$C$16 -> 5817.5 | J28: =J20*'1_PANEL_CONTROL'!$C$16 -> 6175.5 | K28: =K20*'1_PANEL_CONTROL'!$C$16 -> 6623 | ... CI28: =CI20*'1_PANEL_CONTROL'!$C$16 -> 2157576.5
A29: Servicios VetHome CUDI | B29: EUR | C29: Visits * PriceVetHome | D29: =D21*'1_PANEL_CONTROL'!$C$18 -> 150 | E29: =E21*'1_PANEL_CONTROL'!$C$18 -> 300 | F29: =F21*'1_PANEL_CONTROL'!$C$18 -> 450 | G29: =G21*'1_PANEL_CONTROL'!$C$18 -> 675 | H29: =H21*'1_PANEL_CONTROL'!$C$18 -> 825 | I29: =I21*'1_PANEL_CONTROL'!$C$18 -> 975 | J29: =J21*'1_PANEL_CONTROL'!$C$18 -> 1200 | K29: =K21*'1_PANEL_CONTROL'!$C$18 -> 1350 | ... CI29: =CI21*'1_PANEL_CONTROL'!$C$18 -> 686700
A30: Comisiones Marketplace | B30: EUR | C30: MarketplaceUsers * CommissionMarket | D30: =D22*'1_PANEL_CONTROL'!$C$21 -> 33.75 | E30: =E22*'1_PANEL_CONTROL'!$C$21 -> 71.25 | F30: =F22*'1_PANEL_CONTROL'!$C$21 -> 105 | G30: =G22*'1_PANEL_CONTROL'!$C$21 -> 142.5 | H30: =H22*'1_PANEL_CONTROL'!$C$21 -> 180 | I30: =I22*'1_PANEL_CONTROL'!$C$21 -> 221.25 | J30: =J22*'1_PANEL_CONTROL'!$C$21 -> 262.5 | K30: =K22*'1_PANEL_CONTROL'!$C$21 -> 303.75 | ... CI30: =CI22*'1_PANEL_CONTROL'!$C$21 -> 152595
